<?xml version="1.0" encoding="UTF-8"?>
<!-- Generated by org.testng.reporters.JUnitReportReporter -->
<testsuite hostname="Asus-India" name="com.facebook.TestCases.ExtentReportTest" tests="8" failures="2" timestamp="15 Aug 2018 10:05:24 GMT" time="27.351" errors="0">
  <testcase name="ExtTestOne" time="4.464" classname="com.facebook.TestCases.ExtentReportTest"/>
  <testcase name="ExtTestThree" time="1.770" classname="com.facebook.TestCases.ExtentReportTest">
    <failure type="java.lang.AssertionError" message="expected [true] but found [false]">
      <![CDATA[java.lang.AssertionError: expected [true] but found [false]
	at org.testng.Assert.fail(Assert.java:94)
	at org.testng.Assert.failNotEquals(Assert.java:513)
	at org.testng.Assert.assertTrue(Assert.java:42)
	at org.testng.Assert.assertTrue(Assert.java:52)
	at com.facebook.TestCases.ExtentReportTest.ExtTestThree(ExtentReportTest.java:120)
	at sun.reflect.NativeMethodAccessorImpl.invoke0(Native Method)
	at sun.reflect.NativeMethodAccessorImpl.invoke(Unknown Source)
	at sun.reflect.DelegatingMethodAccessorImpl.invoke(Unknown Source)
	at java.lang.reflect.Method.invoke(Unknown Source)
	at org.testng.internal.MethodInvocationHelper.invokeMethod(MethodInvocationHelper.java:86)
	at org.testng.internal.Invoker.invokeMethod(Invoker.java:643)
	at org.testng.internal.Invoker.retryFailed(Invoker.java:967)
	at org.testng.internal.Invoker.invokeTestMethods(Invoker.java:1146)
	at org.testng.internal.TestMethodWorker.invokeTestMethods(TestMethodWorker.java:129)
	at org.testng.internal.TestMethodWorker.run(TestMethodWorker.java:112)
	at java.util.concurrent.ThreadPoolExecutor.runWorker(Unknown Source)
	at java.util.concurrent.ThreadPoolExecutor$Worker.run(Unknown Source)
	at java.lang.Thread.run(Unknown Source)
]]>
    </failure>
  </testcase> <!-- ExtTestThree -->
  <testcase name="ExtTestFour" time="3.419" classname="com.facebook.TestCases.ExtentReportTest"/>
  <testcase name="ExtTestSix" time="4.789" classname="com.facebook.TestCases.ExtentReportTest"/>
  <testcase name="ExtTestTwo" time="1.369" classname="com.facebook.TestCases.ExtentReportTest"/>
  <testcase name="ExtTestFive" time="2.916" classname="com.facebook.TestCases.ExtentReportTest"/>
  <testcase name="ExtTestSeven" time="2.510" classname="com.facebook.TestCases.ExtentReportTest"/>
  <testcase name="ExtTestThree" time="6.114" classname="com.facebook.TestCases.ExtentReportTest">
    <failure type="java.lang.AssertionError" message="expected [true] but found [false]">
      <![CDATA[java.lang.AssertionError: expected [true] but found [false]
	at org.testng.Assert.fail(Assert.java:94)
	at org.testng.Assert.failNotEquals(Assert.java:513)
	at org.testng.Assert.assertTrue(Assert.java:42)
	at org.testng.Assert.assertTrue(Assert.java:52)
	at com.facebook.TestCases.ExtentReportTest.ExtTestThree(ExtentReportTest.java:120)
	at sun.reflect.NativeMethodAccessorImpl.invoke0(Native Method)
	at sun.reflect.NativeMethodAccessorImpl.invoke(Unknown Source)
	at sun.reflect.DelegatingMethodAccessorImpl.invoke(Unknown Source)
	at java.lang.reflect.Method.invoke(Unknown Source)
	at org.testng.internal.MethodInvocationHelper.invokeMethod(MethodInvocationHelper.java:86)
	at org.testng.internal.Invoker.invokeMethod(Invoker.java:643)
	at org.testng.internal.Invoker.invokeTestMethod(Invoker.java:820)
	at org.testng.internal.Invoker.invokeTestMethods(Invoker.java:1128)
	at org.testng.internal.TestMethodWorker.invokeTestMethods(TestMethodWorker.java:129)
	at org.testng.internal.TestMethodWorker.run(TestMethodWorker.java:112)
	at java.util.concurrent.ThreadPoolExecutor.runWorker(Unknown Source)
	at java.util.concurrent.ThreadPoolExecutor$Worker.run(Unknown Source)
	at java.lang.Thread.run(Unknown Source)
]]>
    </failure>
  </testcase> <!-- ExtTestThree -->
</testsuite> <!-- com.facebook.TestCases.ExtentReportTest -->
